[2025-02-05 13:11:19,197] {taskinstance.py:1159} INFO - Dependencies all met for <TaskInstance: grippe_ETL_pipeline.extract_casgrippe manual__2025-02-05T13:08:14.384183+00:00 [queued]>
[2025-02-05 13:11:19,200] {taskinstance.py:1159} INFO - Dependencies all met for <TaskInstance: grippe_ETL_pipeline.extract_casgrippe manual__2025-02-05T13:08:14.384183+00:00 [queued]>
[2025-02-05 13:11:19,200] {taskinstance.py:1356} INFO - 
--------------------------------------------------------------------------------
[2025-02-05 13:11:19,200] {taskinstance.py:1357} INFO - Starting attempt 4 of 4
[2025-02-05 13:11:19,200] {taskinstance.py:1358} INFO - 
--------------------------------------------------------------------------------
[2025-02-05 13:11:19,204] {taskinstance.py:1377} INFO - Executing <Task(PythonOperator): extract_casgrippe> on 2025-02-05 13:08:14.384183+00:00
[2025-02-05 13:11:19,206] {standard_task_runner.py:52} INFO - Started process 8111 to run task
[2025-02-05 13:11:19,208] {standard_task_runner.py:79} INFO - Running: ['***', 'tasks', 'run', 'grippe_ETL_pipeline', 'extract_casgrippe', 'manual__2025-02-05T13:08:14.384183+00:00', '--job-id', '612', '--raw', '--subdir', 'DAGS_FOLDER/influenza-ETL.py', '--cfg-path', '/tmp/tmp3zqz7t1n', '--error-file', '/tmp/tmpyt8re5uj']
[2025-02-05 13:11:19,208] {standard_task_runner.py:80} INFO - Job 612: Subtask extract_casgrippe
[2025-02-05 13:11:19,227] {task_command.py:370} INFO - Running <TaskInstance: grippe_ETL_pipeline.extract_casgrippe manual__2025-02-05T13:08:14.384183+00:00 [running]> on host e70e045b31e0
[2025-02-05 13:11:19,251] {taskinstance.py:1571} INFO - Exporting the following env vars:
AIRFLOW_CTX_DAG_OWNER=***
AIRFLOW_CTX_DAG_ID=grippe_ETL_pipeline
AIRFLOW_CTX_TASK_ID=extract_casgrippe
AIRFLOW_CTX_EXECUTION_DATE=2025-02-05T13:08:14.384183+00:00
AIRFLOW_CTX_TRY_NUMBER=4
AIRFLOW_CTX_DAG_RUN_ID=manual__2025-02-05T13:08:14.384183+00:00
[2025-02-05 13:11:19,375] {taskinstance.py:1889} ERROR - Task failed with exception
Traceback (most recent call last):
  File "/opt/airflow/dags/influenza-ETL.py", line 33, in extract_data
    response.raise_for_status()
  File "/home/airflow/.local/lib/python3.7/site-packages/requests/models.py", line 960, in raise_for_status
    raise HTTPError(http_error_msg, response=self)
requests.exceptions.HTTPError: 429 Client Error: IP '91.168.194.221' have been blocked after several requests exceeding the rate limit for url: https://www.sentiweb.fr/api/v1/datasets/rest/incidence?indicator=3&geo=PAY&span=all

During handling of the above exception, another exception occurred:

Traceback (most recent call last):
  File "/home/airflow/.local/lib/python3.7/site-packages/airflow/operators/python.py", line 171, in execute
    return_value = self.execute_callable()
  File "/home/airflow/.local/lib/python3.7/site-packages/airflow/operators/python.py", line 189, in execute_callable
    return self.python_callable(*self.op_args, **self.op_kwargs)
  File "/opt/airflow/dags/influenza-ETL.py", line 43, in extract_data
    raise Exception(f"❌ Erreur lors de l'extraction des données {data_type} : {e}")
Exception: ❌ Erreur lors de l'extraction des données casgrippe : 429 Client Error: IP '91.168.194.221' have been blocked after several requests exceeding the rate limit for url: https://www.sentiweb.fr/api/v1/datasets/rest/incidence?indicator=3&geo=PAY&span=all
[2025-02-05 13:11:19,381] {taskinstance.py:1400} INFO - Marking task as FAILED. dag_id=grippe_ETL_pipeline, task_id=extract_casgrippe, execution_date=20250205T130814, start_date=20250205T131119, end_date=20250205T131119
[2025-02-05 13:11:19,385] {standard_task_runner.py:97} ERROR - Failed to execute job 612 for task extract_casgrippe (❌ Erreur lors de l'extraction des données casgrippe : 429 Client Error: IP '91.168.194.221' have been blocked after several requests exceeding the rate limit for url: https://www.sentiweb.fr/api/v1/datasets/rest/incidence?indicator=3&geo=PAY&span=all; 8111)
[2025-02-05 13:11:19,395] {local_task_job.py:156} INFO - Task exited with return code 1
[2025-02-05 13:11:19,412] {local_task_job.py:273} INFO - 0 downstream tasks scheduled from follow-on schedule check
