[2025-02-05 14:04:07,325] {taskinstance.py:1159} INFO - Dependencies all met for <TaskInstance: grippe_ETL_pipeline.extract_casgrippe manual__2025-02-05T14:00:14.593042+00:00 [queued]>
[2025-02-05 14:04:07,328] {taskinstance.py:1159} INFO - Dependencies all met for <TaskInstance: grippe_ETL_pipeline.extract_casgrippe manual__2025-02-05T14:00:14.593042+00:00 [queued]>
[2025-02-05 14:04:07,328] {taskinstance.py:1356} INFO - 
--------------------------------------------------------------------------------
[2025-02-05 14:04:07,329] {taskinstance.py:1357} INFO - Starting attempt 2 of 4
[2025-02-05 14:04:07,329] {taskinstance.py:1358} INFO - 
--------------------------------------------------------------------------------
[2025-02-05 14:04:07,333] {taskinstance.py:1377} INFO - Executing <Task(PythonOperator): extract_casgrippe> on 2025-02-05 14:00:14.593042+00:00
[2025-02-05 14:04:07,335] {standard_task_runner.py:52} INFO - Started process 10852 to run task
[2025-02-05 14:04:07,337] {standard_task_runner.py:79} INFO - Running: ['***', 'tasks', 'run', 'grippe_ETL_pipeline', 'extract_casgrippe', 'manual__2025-02-05T14:00:14.593042+00:00', '--job-id', '631', '--raw', '--subdir', 'DAGS_FOLDER/influenza-ETL.py', '--cfg-path', '/tmp/tmp6en6c1bn', '--error-file', '/tmp/tmpktnpb16_']
[2025-02-05 14:04:07,337] {standard_task_runner.py:80} INFO - Job 631: Subtask extract_casgrippe
[2025-02-05 14:04:07,363] {task_command.py:370} INFO - Running <TaskInstance: grippe_ETL_pipeline.extract_casgrippe manual__2025-02-05T14:00:14.593042+00:00 [running]> on host e70e045b31e0
[2025-02-05 14:04:07,390] {taskinstance.py:1571} INFO - Exporting the following env vars:
AIRFLOW_CTX_DAG_OWNER=***
AIRFLOW_CTX_DAG_ID=grippe_ETL_pipeline
AIRFLOW_CTX_TASK_ID=extract_casgrippe
AIRFLOW_CTX_EXECUTION_DATE=2025-02-05T14:00:14.593042+00:00
AIRFLOW_CTX_TRY_NUMBER=2
AIRFLOW_CTX_DAG_RUN_ID=manual__2025-02-05T14:00:14.593042+00:00
[2025-02-05 14:04:07,474] {taskinstance.py:1889} ERROR - Task failed with exception
Traceback (most recent call last):
  File "/opt/airflow/dags/influenza-ETL.py", line 33, in extract_data
    response.raise_for_status()
  File "/home/airflow/.local/lib/python3.7/site-packages/requests/models.py", line 960, in raise_for_status
    raise HTTPError(http_error_msg, response=self)
requests.exceptions.HTTPError: 429 Client Error: IP '91.168.194.221' have been blocked after several requests exceeding the rate limit for url: https://www.sentiweb.fr/api/v1/datasets/rest/incidence?indicator=3&geo=PAY&span=all

During handling of the above exception, another exception occurred:

Traceback (most recent call last):
  File "/home/airflow/.local/lib/python3.7/site-packages/airflow/operators/python.py", line 171, in execute
    return_value = self.execute_callable()
  File "/home/airflow/.local/lib/python3.7/site-packages/airflow/operators/python.py", line 189, in execute_callable
    return self.python_callable(*self.op_args, **self.op_kwargs)
  File "/opt/airflow/dags/influenza-ETL.py", line 43, in extract_data
    raise Exception(f"❌ Erreur lors de l'extraction des données {data_type} : {e}")
Exception: ❌ Erreur lors de l'extraction des données casgrippe : 429 Client Error: IP '91.168.194.221' have been blocked after several requests exceeding the rate limit for url: https://www.sentiweb.fr/api/v1/datasets/rest/incidence?indicator=3&geo=PAY&span=all
[2025-02-05 14:04:07,479] {taskinstance.py:1400} INFO - Marking task as UP_FOR_RETRY. dag_id=grippe_ETL_pipeline, task_id=extract_casgrippe, execution_date=20250205T140014, start_date=20250205T140407, end_date=20250205T140407
[2025-02-05 14:04:07,483] {standard_task_runner.py:97} ERROR - Failed to execute job 631 for task extract_casgrippe (❌ Erreur lors de l'extraction des données casgrippe : 429 Client Error: IP '91.168.194.221' have been blocked after several requests exceeding the rate limit for url: https://www.sentiweb.fr/api/v1/datasets/rest/incidence?indicator=3&geo=PAY&span=all; 10852)
[2025-02-05 14:04:07,519] {local_task_job.py:156} INFO - Task exited with return code 1
[2025-02-05 14:04:07,536] {local_task_job.py:273} INFO - 0 downstream tasks scheduled from follow-on schedule check
